Workbook

Sheet README
A1: Student Application Tracker – Prototype
A3: This is a prototype built with fictional sample data. All names, IDs, dates and staff are made up. It contains no real student or company information.

Sheet APPLICANTS
A1: Student ID | B1: Name | C1: Country | D1: Office | E1: Course | F1: Institution | G1: Intake | H1: Enquiry Date | I1: Status | J1: Docs Complete | K1: Missing Documents | L1: Next Deadline | M1: Days to Deadline | N1: Priority | O1: Owner | P1: Action
A2: STU-001 | B2: Test Student | I2: Applied | L2: 46285 | M2: =IF(OR(L2="",I2="Arrived",I2="Withdrawn"),"",L2-TODAY()) -> -6 | N2: =IF(A2="","",IF(OR(I2="Arrived",I2="Withdrawn"),"Closed",IF(M2="","No deadline",IF(M2<0,"Overdue",IF(M2<=7,"Due this week",IF(M2<=14,"Due soon","On track")))))) -> Overdue | P2: =IF(OR(N2="Overdue",N2="Due this week"),COUNTIF(N$2:N2,"Overdue")+COUNTIF(N$2:N2,"Due this week"),"") -> 1
A3: STU-002 | B3: Chioma Obi | C3: Kenya | D3: Dublin | E3: MBA | F3: Griffith College | G3: Sept 2026 | H3: 46056 | I3: Arrived | J3: Y | M3: =IF(OR(L3="",I3="Arrived",I3="Withdrawn"),"",L3-TODAY()) | N3: =IF(A3="","",IF(OR(I3="Arrived",I3="Withdrawn"),"Closed",IF(M3="","No deadline",IF(M3<0,"Overdue",IF(M3<=7,"Due this week",IF(M3<=14,"Due soon","On track")))))) -> Closed | O3: Advisor 3 | P3: =IF(OR(N3="Overdue",N3="Due this week"),COUNTIF(N$2:N3,"Overdue")+COUNTIF(N$2:N3,"Due this week"),"")
A4: STU-003 | B4: Kelechi Bello | C4: Nigeria | D4: Abuja | E4: MBA | F4: Griffith College | G4: Sept 2027 | H4: 46160 | I4: Visa | J4: Y | L4: 46318 | M4: =IF(OR(L4="",I4="Arrived",I4="Withdrawn"),"",L4-TODAY()) -> 27 | N4: =IF(A4="","",IF(OR(I4="Arrived",I4="Withdrawn"),"Closed",IF(M4="","No deadline",IF(M4<0,"Overdue",IF(M4<=7,"Due this week",IF(M4<=14,"Due soon","On track")))))) -> On track | O4: Advisor 2 | P4: =IF(OR(N4="Overdue",N4="Due this week"),COUNTIF(N$2:N4,"Overdue")+COUNTIF(N$2:N4,"Due this week"),"")
A5: STU-004 | B5: Emeka Balogun | C5: Nigeria | D5: Dublin | E5: MEng Electronic and Computer Engineering | F5: Dublin City University | G5: Jan 2027 | H5: 46271 | I5: Offer | J5: Y | L5: 46307 | M5: =IF(OR(L5="",I5="Arrived",I5="Withdrawn"),"",L5-TODAY()) -> 16 | N5: =IF(A5="","",IF(OR(I5="Arrived",I5="Withdrawn"),"Closed",IF(M5="","No deadline",IF(M5<0,"Overdue",IF(M5<=7,"Due this week",IF(M5<=14,"Due soon","On track")))))) -> On track | O5: Advisor 3 | P5: =IF(OR(N5="Overdue",N5="Due this week"),COUNTIF(N$2:N5,"Overdue")+COUNTIF(N$2:N5,"Due this week"),"")
A6: STU-005 | B6: Tunde Adeyemi | C6: Nigeria | D6: Dublin | E6: MEng Mechanical Engineering | F6: University of Limerick | G6: Jan 2027 | H6: 46215 | I6: Enquiry | J6: N | K6: Transcript, English test, Passport | L6: 46316 | M6: =IF(OR(L6="",I6="Arrived",I6="Withdrawn"),"",L6-TODAY()) -> 25 | N6: =IF(A6="","",IF(OR(I6="Arrived",I6="Withdrawn"),"Closed",IF(M6="","No deadline",IF(M6<0,"Overdue",IF(M6<=7,"Due this week",IF(M6<=14,"Due soon","On track")))))) -> On track | O6: Advisor 3 | P6: =IF(OR(N6="Overdue",N6="Due this week"),COUNTIF(N$2:N6,"Overdue")+COUNTIF(N$2:N6,"Due this week"),"")
A7: STU-006 | B7: Segun Olawale | C7: Nigeria | D7: Dublin | E7: MSc Computing | F7: Dublin City University | G7: Jan 2027 | H7: 46209 | I7: Enquiry | J7: N | K7: Personal statement, Passport | L7: 46314 | M7: =IF(OR(L7="",I7="Arrived",I7="Withdrawn"),"",L7-TODAY()) -> 23 | N7: =IF(A7="","",IF(OR(I7="Arrived",I7="Withdrawn"),"Closed",IF(M7="","No deadline",IF(M7<0,"Overdue",IF(M7<=7,"Due this week",IF(M7<=14,"Due soon","On track")))))) -> On track | O7: Advisor 2 | P7: =IF(OR(N7="Overdue",N7="Due this week"),COUNTIF(N$2:N7,"Overdue")+COUNTIF(N$2:N7,"Due this week"),"")
A8: STU-007 | B8: Blessing Adebayo | C8: Nigeria | D8: Abuja | E8: MEng Electronic and Computer Engineering | F8: Dublin City University | G8: Jan 2027 | H8: 46257 | I8: Applied | J8: N | K8: Proof of funds | L8: 46285 | M8: =IF(OR(L8="",I8="Arrived",I8="Withdrawn"),"",L8-TODAY()) -> -6 | N8: =IF(A8="","",IF(OR(I8="Arrived",I8="Withdrawn"),"Closed",IF(M8="","No deadline",IF(M8<0,"Overdue",IF(M8<=7,"Due this week",IF(M8<=14,"Due soon","On track")))))) -> Overdue | O8: Advisor 1 | P8: =IF(OR(N8="Overdue",N8="Due this week"),COUNTIF(N$2:N8,"Overdue")+COUNTIF(N$2:N8,"Due this week"),"") -> 2
A9: STU-008 | B9: Femi Okafor | C9: Nigeria | D9: Dublin | E9: MEng Electronic and Computer Engineering | F9: Dublin City University | G9: Jan 2027 | H9: 46113 | I9: Documents | J9: N | K9: English test, Personal statement | L9: 46305 | M9: =IF(OR(L9="",I9="Arrived",I9="Withdrawn"),"",L9-TODAY()) -> 14 | N9: =IF(A9="","",IF(OR(I9="Arrived",I9="Withdrawn"),"Closed",IF(M9="","No deadline",IF(M9<0,"Overdue",IF(M9<=7,"Due this week",IF(M9<=14,"Due soon","On track")))))) -> Due soon | O9: Advisor 1 | P9: =IF(OR(N9="Overdue",N9="Due this week"),COUNTIF(N$2:N9,"Overdue")+COUNTIF(N$2:N9,"Due this week"),"")
A10: STU-009 | B10: Blessing Mensah | C10: Nigeria | D10: Dublin | E10: MSc Software Engineering | F10: TU Dublin | G10: Jan 2027 | H10: 46249 | I10: Documents | J10: N | K10: Transcript, English test | L10: 46287 | M10: =IF(OR(L10="",I10="Arrived",I10="Withdrawn"),"",L10-TODAY()) -> -4 | N10: =IF(A10="","",IF(OR(I10="Arrived",I10="Withdrawn"),"Closed",IF(M10="","No deadline",IF(M10<0,"Overdue",IF(M10<=7,"Due this week",IF(M10<=14,"Due soon","On track")))))) -> Overdue | O10: Advisor 1 | P10: =IF(OR(N10="Overdue",N10="Due this week"),COUNTIF(N$2:N10,"Overdue")+COUNTIF(N$2:N10,"Due this week"),"") -> 3
A11: STU-010 | B11: Amaka Ibe | C11: Nigeria | D11: Abuja | E11: MSc Data Analytics | F11: University of Limerick | G11: Sept 2027 | H11: 46144 | I11: Visa | J11: Y | L11: 46314 | M11: =IF(OR(L11="",I11="Arrived",I11="Withdrawn"),"",L11-TODAY()) -> 23 | N11: =IF(A11="","",IF(OR(I11="Arrived",I11="Withdrawn"),"Closed",IF(M11="","No deadline",IF(M11<0,"Overdue",IF(M11<=7,"Due this week",IF(M11<=14,"Due soon","On track")))))) -> On track | O11: Advisor 1 | P11: =IF(OR(N11="Overdue",N11="Due this week"),COUNTIF(N$2:N11,"Overdue")+COUNTIF(N$2:N11,"Due this week"),"")
A12: STU-011 | B12: Daniel Nwosu | C12: Nigeria | D12: Dublin | E12: MSc Business Analytics | F12: University of Galway | G12: Jan 2027 | H12: 46197 | I12: Applied | J12: N | K12: Reference letter | L12: 46279 | M12: =IF(OR(L12="",I12="Arrived",I12="Withdrawn"),"",L12-TODAY()) -> -12 | N12: =IF(A12="","",IF(OR(I12="Arrived",I12="Withdrawn"),"Closed",IF(M12="","No deadline",IF(M12<0,"Overdue",IF(M12<=7,"Due this week",IF(M12<=14,"Due soon","On track")))))) -> Overdue | O12: Advisor 1 | P12: =IF(OR(N12="Overdue",N12="Due this week"),COUNTIF(N$2:N12,"Overdue")+COUNTIF(N$2:N12,"Due this week"),"") -> 4
A13: STU-012 | B13: Hauwa Asante | C13: Nigeria | D13: Abuja | E13: MSc Computing | F13: Dublin City University | G13: Jan 2027 | H13: 46077 | I13: Offer | J13: N | K13: Proof of funds | L13: 46307 | M13: =IF(OR(L13="",I13="Arrived",I13="Withdrawn"),"",L13-TODAY()) -> 16 | N13: =IF(A13="","",IF(OR(I13="Arrived",I13="Withdrawn"),"Closed",IF(M13="","No deadline",IF(M13<0,"Overdue",IF(M13<=7,"Due this week",IF(M13<=14,"Due soon","On track")))))) -> On track | O13: Advisor 3 | P13: =IF(OR(N13="Overdue",N13="Due this week"),COUNTIF(N$2:N13,"Overdue")+COUNTIF(N$2:N13,"Due this week"),"")
A14: STU-013 | B14: Bola Ogunleye | C14: Nigeria | D14: Dublin | E14: MSc Computing | F14: Dublin City University | G14: Sept 2027 | H14: 46180 | I14: Applied | J14: N | K14: English test | L14: 46294 | M14: =IF(OR(L14="",I14="Arrived",I14="Withdrawn"),"",L14-TODAY()) -> 3 | N14: =IF(A14="","",IF(OR(I14="Arrived",I14="Withdrawn"),"Closed",IF(M14="","No deadline",IF(M14<0,"Overdue",IF(M14<=7,"Due this week",IF(M14<=14,"Due soon","On track")))))) -> Due this week | O14: Advisor 2 | P14: =IF(OR(N14="Overdue",N14="Due this week"),COUNTIF(N$2:N14,"Overdue")+COUNTIF(N$2:N14,"Due this week"),"") -> 5
A15: STU-014 | B15: Ama Ibe | C15: Nigeria | D15: Abuja | E15: MBA | F15: Griffith College | G15: Sept 2027 | H15: 46065 | I15: Enquiry | J15: N | K15: Degree certificate, English test, Reference letter | L15: 46288 | M15: =IF(OR(L15="",I15="Arrived",I15="Withdrawn"),"",L15-TODAY()) -> -3 | N15: =IF(A15="","",IF(OR(I15="Arrived",I15="Withdrawn"),"Closed",IF(M15="","No deadline",IF(M15<0,"Overdue",IF(M15<=7,"Due this week",IF(M15<=14,"Due soon","On track")))))) -> Overdue | O15: Advisor 3 | P15: =IF(OR(N15="Overdue",N15="Due this week"),COUNTIF(N$2:N15,"Overdue")+COUNTIF(N$2:N15,"Due this week"),"") -> 6
A16: STU-015 | B16: Zainab Okoro | C16: Nigeria | D16: Abuja | E16: MSc Project Management | F16: TU Dublin | G16: Jan 2027 | H16: 46262 | I16: Documents | J16: N | K16: Personal statement | L16: 46309 | M16: =IF(OR(L16="",I16="Arrived",I16="Withdrawn"),"",L16-TODAY()) -> 18 | N16: =IF(A16="","",IF(OR(I16="Arrived",I16="Withdrawn"),"Closed",IF(M16="","No deadline",IF(M16<0,"Overdue",IF(M16<=7,"Due this week",IF(M16<=14,"Due soon","On track")))))) -> On track | O16: Advisor 1 | P16: =IF(OR(N16="Overdue",N16="Due this week"),COUNTIF(N$2:N16,"Overdue")+COUNTIF(N$2:N16,"Due this week"),"")
A17: STU-016 | B17: Ngozi Adeyemi | C17: Ghana | D17: Dublin | E17: MSc Software Engineering | F17: TU Dublin | G17: Jan 2027 | H17: 46149 | I17: Applied | J17: N | K17: English test | L17: 46295 | M17: =IF(OR(L17="",I17="Arrived",I17="Withdrawn"),"",L17-TODAY()) -> 4 | N17: =IF(A17="","",IF(OR(I17="Arrived",I17="Withdrawn"),"Closed",IF(M17="","No deadline",IF(M17<0,"Overdue",IF(M17<=7,"Due this week",IF(M17<=14,"Due soon","On track")))))) -> Due this week | O17: Advisor 2 | P17: =IF(OR(N17="Overdue",N17="Due this week"),COUNTIF(N$2:N17,"Overdue")+COUNTIF(N$2:N17,"Due this week"),"") -> 7
A18: STU-017 | B18: Grace Bello | C18: Nigeria | D18: Abuja | E18: MSc Computing | F18: Dublin City University | G18: Sept 2026 | H18: 46152 | I18: Arrived | J18: Y | M18: =IF(OR(L18="",I18="Arrived",I18="Withdrawn"),"",L18-TODAY()) | N18: =IF(A18="","",IF(OR(I18="Arrived",I18="Withdrawn"),"Closed",IF(M18="","No deadline",IF(M18<0,"Overdue",IF(M18<=7,"Due this week",IF(M18<=14,"Due soon","On track")))))) -> Closed | O18: Advisor 3 | P18: =IF(OR(N18="Overdue",N18="Due this week"),COUNTIF(N$2:N18,"Overdue")+COUNTIF(N$2:N18,"Due this week"),"")
A19: STU-018 | B19: Wanjiru Asante | C19: Nigeria | D19: Abuja | E19: MSc Software Engineering | F19: TU Dublin | G19: Sept 2027 | H19: 46169 | I19: Offer | J19: N | K19: Proof of funds | L19: 46280 | M19: =IF(OR(L19="",I19="Arrived",I19="Withdrawn"),"",L19-TODAY()) -> -11 | N19: =IF(A19="","",IF(OR(I19="Arrived",I19="Withdrawn"),"Closed",IF(M19="","No deadline",IF(M19<0,"Overdue",IF(M19<=7,"Due this week",IF(M19<=14,"Due soon","On track")))))) -> Overdue | O19: Advisor 2 | P19: =IF(OR(N19="Overdue",N19="Due this week"),COUNTIF(N$2:N19,"Overdue")+COUNTIF(N$2:N19,"Due this week"),"") -> 8
A20: STU-019 | B20: Zainab Adeyemi | C20: Nigeria | D20: Abuja | E20: MSc Software Engineering | F20: TU Dublin | G20: Jan 2027 | H20: 46159 | I20: Enquiry | J20: N | K20: Proof of funds, Reference letter | L20: 46284 | M20: =IF(OR(L20="",I20="Arrived",I20="Withdrawn"),"",L20-TODAY()) -> -7 | N20: =IF(A20="","",IF(OR(I20="Arrived",I20="Withdrawn"),"Closed",IF(M20="","No deadline",IF(M20<0,"Overdue",IF(M20<=7,"Due this week",IF(M20<=14,"Due soon","On track")))))) -> Overdue | O20: Advisor 2 | P20: =IF(OR(N20="Overdue",N20="Due this week"),COUNTIF(N$2:N20,"Overdue")+COUNTIF(N$2:N20,"Due this week"),"") -> 9
A21: STU-020 | B21: Kofi Danjuma | C21: Nigeria | D21: Dublin | E21: MSc Data Analytics | F21: University of Limerick | G21: Jan 2027 | H21: 46195 | I21: Offer | J21: Y | L21: 46309 | M21: =IF(OR(L21="",I21="Arrived",I21="Withdrawn"),"",L21-TODAY()) -> 18 | N21: =IF(A21="","",IF(OR(I21="Arrived",I21="Withdrawn"),"Closed",IF(M21="","No deadline",IF(M21<0,"Overdue",IF(M21<=7,"Due this week",IF(M21<=14,"Due soon","On track")))))) -> On track | O21: Advisor 1 | P21: =IF(OR(N21="Overdue",N21="Due this week"),COUNTIF(N$2:N21,"Overdue")+COUNTIF(N$2:N21,"Due this week"),"")
A22: STU-021 | B22: Chidi Asante | C22: Nigeria | D22: Abuja | E22: MBA | F22: Griffith College | G22: Jan 2027 | H22: 46159 | I22: Offer | J22: N | K22: Reference letter | L22: 46287 | M22: =IF(OR(L22="",I22="Arrived",I22="Withdrawn"),"",L22-TODAY()) -> -4 | N22: =IF(A22="","",IF(OR(I22="Arrived",I22="Withdrawn"),"Closed",IF(M22="","No deadline",IF(M22<0,"Overdue",IF(M22<=7,"Due this week",IF(M22<=14,"Due soon","On track")))))) -> Overdue | O22: Advisor 3 | P22: =IF(OR(N22="Overdue",N22="Due this week"),COUNTIF(N$2:N22,"Overdue")+COUNTIF(N$2:N22,"Due this week"),"") -> 10
A23: STU-022 | B23: Uche Adeyemi | C23: Nigeria | D23: Abuja | E23: MSc Data Analytics | F23: University of Limerick | G23: Sept 2026 | H23: 46253 | I23: Arrived | J23: Y | M23: =IF(OR(L23="",I23="Arrived",I23="Withdrawn"),"",L23-TODAY()) | N23: =IF(A23="","",IF(OR(I23="Arrived",I23="Withdrawn"),"Closed",IF(M23="","No deadline",IF(M23<0,"Overdue",IF(M23<=7,"Due this week",IF(M23<=14,"Due soon","On track")))))) -> Closed | O23: Advisor 3 | P23: =IF(OR(N23="Overdue",N23="Due this week"),COUNTIF(N$2:N23,"Overdue")+COUNTIF(N$2:N23,"Due this week"),"")
A24: STU-023 | B24: Ahmed Balogun | C24: Nigeria | D24: Abuja | E24: MSc Business Analytics | F24: University of Galway | G24: Sept 2026 | H24: 46128 | I24: Arrived | J24: Y | M24: =IF(OR(L24="",I24="Arrived",I24="Withdrawn"),"",L24-TODAY()) | N24: =IF(A24="","",IF(OR(I24="Arrived",I24="Withdrawn"),"Closed",IF(M24="","No deadline",IF(M24<0,"Overdue",IF(M24<=7,"Due this week",IF(M24<=14,"Due soon","On track")))))) -> Closed | O24: Advisor 1 | P24: =IF(OR(N24="Overdue",N24="Due this week"),COUNTIF(N$2:N24,"Overdue")+COUNTIF(N$2:N24,"Due this week"),"")
A25: STU-024 | B25: Ama Owusu | C25: Nigeria | D25: Abuja | E25: MEng Electronic and Computer Engineering | F25: Dublin City University | G25: Jan 2027 | H25: 46049 | I25: Applied | J25: Y | L25: 46284 | M25: =IF(OR(L25="",I25="Arrived",I25="Withdrawn"),"",L25-TODAY()) -> -7 | N25: =IF(A25="","",IF(OR(I25="Arrived",I25="Withdrawn"),"Closed",IF(M25="","No deadline",IF(M25<0,"Overdue",IF(M25<=7,"Due this week",IF(M25<=14,"Due soon","On track")))))) -> Overdue | O25: Advisor 2 | P25: =IF(OR(N25="Overdue",N25="Due this week"),COUNTIF(N$2:N25,"Overdue")+COUNTIF(N$2:N25,"Due this week"),"") -> 11
A26: STU-025 | B26: Daniel Abubakar | C26: Nigeria | D26: Abuja | E26: MBA | F26: Griffith College | G26: Sept 2027 | H26: 46121 | I26: Applied | J26: Y | L26: 46284 | M26: =IF(OR(L26="",I26="Arrived",I26="Withdrawn"),"",L26-TODAY()) -> -7 | N26: =IF(A26="","",IF(OR(I26="Arrived",I26="Withdrawn"),"Closed",IF(M26="","No deadline",IF(M26<0,"Overdue",IF(M26<=7,"Due this week",IF(M26<=14,"Due soon","On track")))))) -> Overdue | O26: Advisor 1 | P26: =IF(OR(N26="Overdue",N26="Due this week"),COUNTIF(N$2:N26,"Overdue")+COUNTIF(N$2:N26,"Due this week"),"") -> 12
A27: STU-026 | B27: Ahmed Okafor | C27: Nigeria | D27: Abuja | E27: MSc Computing | F27: Dublin City University | G27: Sept 2027 | H27: 46180 | I27: Documents | J27: N | K27: Reference letter, Proof of funds | L27: 46310 | M27: =IF(OR(L27="",I27="Arrived",I27="Withdrawn"),"",L27-TODAY()) -> 19 | N27: =IF(A27="","",IF(OR(I27="Arrived",I27="Withdrawn"),"Closed",IF(M27="","No deadline",IF(M27<0,"Overdue",IF(M27<=7,"Due this week",IF(M27<=14,"Due soon","On track")))))) -> On track | O27: Advisor 2 | P27: =IF(OR(N27="Overdue",N27="Due this week"),COUNTIF(N$2:N27,"Overdue")+COUNTIF(N$2:N27,"Due this week"),"")
A28: STU-027 | B28: Emeka Asante | C28: Nigeria | D28: Abuja | E28: MSc Data Analytics | F28: University of Limerick | G28: Jan 2027 | H28: 46104 | I28: Documents | J28: N | K28: Personal statement, English test | L28: 46294 | M28: =IF(OR(L28="",I28="Arrived",I28="Withdrawn"),"",L28-TODAY()) -> 3 | N28: =IF(A28="","",IF(OR(I28="Arrived",I28="Withdrawn"),"Closed",IF(M28="","No deadline",IF(M28<0,"Overdue",IF(M28<=7,"Due this week",IF(M28<=14,"Due soon","On track")))))) -> Due this week | O28: Advisor 2 | P28: =IF(OR(N28="Overdue",N28="Due this week"),COUNTIF(N$2:N28,"Overdue")+COUNTIF(N$2:N28,"Due this week"),"") -> 13
A29: STU-028 | B29: Kelechi Kamau | C29: Nigeria | D29: Dublin | E29: MEng Mechanical Engineering | F29: University of Limerick | G29: Jan 2027 | H29: 46193 | I29: Visa | J29: Y | L29: 46303 | M29: =IF(OR(L29="",I29="Arrived",I29="Withdrawn"),"",L29-TODAY()) -> 12 | N29: =IF(A29="","",IF(OR(I29="Arrived",I29="Withdrawn"),"Closed",IF(M29="","No deadline",IF(M29<0,"Overdue",IF(M29<=7,"Due this week",IF(M29<=14,"Due soon","On track")))))) -> Due soon | O29: Advisor 1 | P29: =IF(OR(N29="Overdue",N29="Due this week"),COUNTIF(N$2:N29,"Overdue")+COUNTIF(N$2:N29,"Due this week"),"")
A30: STU-029 | B30: Emeka Nwosu | C30: Nigeria | D30: Abuja | E30: MEng Electronic and Computer Engineering | F30: Dublin City University | G30: Jan 2027 | H30: 46154 | I30: Applied | J30: Y | L30: 46289 | M30: =IF(OR(L30="",I30="Arrived",I30="Withdrawn"),"",L30-TODAY()) -> -2 | N30: =IF(A30="","",IF(OR(I30="Arrived",I30="Withdrawn"),"Closed",IF(M30="","No deadline",IF(M30<0,"Overdue",IF(M30<=7,"Due this week",IF(M30<=14,"Due soon","On track")))))) -> Overdue | O30: Advisor 2 | P30: =IF(OR(N30="Overdue",N30="Due this week"),COUNTIF(N$2:N30,"Overdue")+COUNTIF(N$2:N30,"Due this week"),"") -> 14
A31: STU-030 | B31: Ibrahim Okoro | C31: Kenya | D31: Dublin | E31: MSc Business Analytics | F31: University of Galway | G31: Sept 2026 | H31: 46194 | I31: Arrived | J31: Y | M31: =IF(OR(L31="",I31="Arrived",I31="Withdrawn"),"",L31-TODAY()) | N31: =IF(A31="","",IF(OR(I31="Arrived",I31="Withdrawn"),"Closed",IF(M31="","No deadline",IF(M31<0,"Overdue",IF(M31<=7,"Due this week",IF(M31<=14,"Due soon","On track")))))) -> Closed | O31: Advisor 3 | P31: =IF(OR(N31="Overdue",N31="Due this week"),COUNTIF(N$2:N31,"Overdue")+COUNTIF(N$2:N31,"Due this week"),"")
A32: STU-031 | B32: Ada Asante | C32: Nigeria | D32: Dublin | E32: MSc Computing | F32: Dublin City University | G32: Jan 2027 | H32: 46093 | I32: Applied | J32: Y | L32: 46317 | M32: =IF(OR(L32="",I32="Arrived",I32="Withdrawn"),"",L32-TODAY()) -> 26 | N32: =IF(A32="","",IF(OR(I32="Arrived",I32="Withdrawn"),"Closed",IF(M32="","No deadline",IF(M32<0,"Overdue",IF(M32<=7,"Due this week",IF(M32<=14,"Due soon","On track")))))) -> On track | O32: Advisor 2 | P32: =IF(OR(N32="Overdue",N32="Due this week"),COUNTIF(N$2:N32,"Overdue")+COUNTIF(N$2:N32,"Due this week"),"")
A33: STU-032 | B33: Kwame Chukwu | C33: Nigeria | D33: Abuja | E33: MEng Electronic and Computer Engineering | F33: Dublin City University | G33: Jan 2027 | H33: 46075 | I33: Documents | J33: N | K33: Degree certificate, English test, Personal statement | L33: 46280 | M33: =IF(OR(L33="",I33="Arrived",I33="Withdrawn"),"",L33-TODAY()) -> -11 | N33: =IF(A33="","",IF(OR(I33="Arrived",I33="Withdrawn"),"Closed",IF(M33="","No deadline",IF(M33<0,"Overdue",IF(M33<=7,"Due this week",IF(M33<=14,"Due soon","On track")))))) -> Overdue | O33: Advisor 1 | P33: =IF(OR(N33="Overdue",N33="Due this week"),COUNTIF(N$2:N33,"Overdue")+COUNTIF(N$2:N33,"Due this week"),"") -> 15
A34: STU-033 | B34: Musa Adeyemi | C34: Nigeria | D34: Dublin | E34: MSc Computing | F34: Dublin City University | G34: Jan 2027 | H34: 46137 | I34: Withdrawn | J34: Y | M34: =IF(OR(L34="",I34="Arrived",I34="Withdrawn"),"",L34-TODAY()) | N34: =IF(A34="","",IF(OR(I34="Arrived",I34="Withdrawn"),"Closed",IF(M34="","No deadline",IF(M34<0,"Overdue",IF(M34<=7,"Due this week",IF(M34<=14,"Due soon","On track")))))) -> Closed | O34: Advisor 3 | P34: =IF(OR(N34="Overdue",N34="Due this week"),COUNTIF(N$2:N34,"Overdue")+COUNTIF(N$2:N34,"Due this week"),"")
A35: STU-034 | B35: Wanjiru Chukwu | C35: Kenya | D35: Abuja | E35: MEng Mechanical Engineering | F35: University of Limerick | G35: Jan 2027 | H35: 46229 | I35: Withdrawn | J35: Y | M35: =IF(OR(L35="",I35="Arrived",I35="Withdrawn"),"",L35-TODAY()) | N35: =IF(A35="","",IF(OR(I35="Arrived",I35="Withdrawn"),"Closed",IF(M35="","No deadline",IF(M35<0,"Overdue",IF(M35<=7,"Due this week",IF(M35<=14,"Due soon","On track")))))) -> Closed | O35: Advisor 3 | P35: =IF(OR(N35="Overdue",N35="Due this week"),COUNTIF(N$2:N35,"Overdue")+COUNTIF(N$2:N35,"Due this week"),"")
A36: STU-035 | B36: Chidi Olawale | C36: Nigeria | D36: Abuja | E36: MEng Electronic and Computer Engineering | F36: Dublin City University | G36: Jan 2027 | H36: 46057 | I36: Offer | J36: N | K36: Reference letter | L36: 46313 | M36: =IF(OR(L36="",I36="Arrived",I36="Withdrawn"),"",L36-TODAY()) -> 22 | N36: =IF(A36="","",IF(OR(I36="Arrived",I36="Withdrawn"),"Closed",IF(M36="","No deadline",IF(M36<0,"Overdue",IF(M36<=7,"Due this week",IF(M36<=14,"Due soon","On track")))))) -> On track | O36: Advisor 3 | P36: =IF(OR(N36="Overdue",N36="Due this week"),COUNTIF(N$2:N36,"Overdue")+COUNTIF(N$2:N36,"Due this week"),"")
A37: STU-036 | B37: Joy Adebayo | C37: Nigeria | D37: Abuja | E37: MSc Business Analytics | F37: University of Galway | G37: Jan 2027 | H37: 46134 | I37: Enquiry | J37: N | K37: English test | L37: 46291 | M37: =IF(OR(L37="",I37="Arrived",I37="Withdrawn"),"",L37-TODAY()) -> 0 | N37: =IF(A37="","",IF(OR(I37="Arrived",I37="Withdrawn"),"Closed",IF(M37="","No deadline",IF(M37<0,"Overdue",IF(M37<=7,"Due this week",IF(M37<=14,"Due soon","On track")))))) -> Due this week | O37: Advisor 3 | P37: =IF(OR(N37="Overdue",N37="Due this week"),COUNTIF(N$2:N37,"Overdue")+COUNTIF(N$2:N37,"Due this week"),"") -> 16
A38: STU-037 | B38: Wanjiru Danjuma | C38: Nigeria | D38: Abuja | E38: MSc Public Health | F38: University College Cork | G38: Jan 2027 | H38: 46090 | I38: Visa | J38: Y | L38: 46299 | M38: =IF(OR(L38="",I38="Arrived",I38="Withdrawn"),"",L38-TODAY()) -> 8 | N38: =IF(A38="","",IF(OR(I38="Arrived",I38="Withdrawn"),"Closed",IF(M38="","No deadline",IF(M38<0,"Overdue",IF(M38<=7,"Due this week",IF(M38<=14,"Due soon","On track")))))) -> Due soon | O38: Advisor 3 | P38: =IF(OR(N38="Overdue",N38="Due this week"),COUNTIF(N$2:N38,"Overdue")+COUNTIF(N$2:N38,"Due this week"),"")
A39: STU-038 | B39: Ibrahim Eze | C39: Nigeria | D39: Abuja | E39: MSc Business Analytics | F39: University of Galway | G39: Sept 2027 | H39: 46091 | I39: Documents | J39: N | K39: Passport | L39: 46329 | M39: =IF(OR(L39="",I39="Arrived",I39="Withdrawn"),"",L39-TODAY()) -> 38 | N39: =IF(A39="","",IF(OR(I39="Arrived",I39="Withdrawn"),"Closed",IF(M39="","No deadline",IF(M39<0,"Overdue",IF(M39<=7,"Due this week",IF(M39<=14,"Due soon","On track")))))) -> On track | O39: Advisor 1 | P39: =IF(OR(N39="Overdue",N39="Due this week"),COUNTIF(N$2:N39,"Overdue")+COUNTIF(N$2:N39,"Due this week"),"")
A40: STU-039 | B40: Uche Danjuma | C40: Nigeria | D40: Abuja | E40: MBA | F40: Griffith College | G40: Jan 2027 | H40: 46067 | I40: Enquiry | J40: N | K40: Proof of funds, English test | L40: 46310 | M40: =IF(OR(L40="",I40="Arrived",I40="Withdrawn"),"",L40-TODAY()) -> 19 | N40: =IF(A40="","",IF(OR(I40="Arrived",I40="Withdrawn"),"Closed",IF(M40="","No deadline",IF(M40<0,"Overdue",IF(M40<=7,"Due this week",IF(M40<=14,"Due soon","On track")))))) -> On track | O40: Advisor 1 | P40: =IF(OR(N40="Overdue",N40="Due this week"),COUNTIF(N$2:N40,"Overdue")+COUNTIF(N$2:N40,"Due this week"),"")
...

Sheet LISTS
A1: Status | B1: Office | C1: Intake | D1: Docs Complete | E1: Owner
A2: Enquiry | B2: Dublin | C2: 46023 | D2: Y | E2: Advisor 1
A3: Documents | B3: Abuja | C3: 46266 | D3: N | E3: Advisor 2
A4: Applied | C4: 46388 | E4: Advisor 3
A5: Offer | C5: 46631
A6: Visa
A7: Arrived
A8: Withdrawn

Sheet ACTION LIST
A1: Action List: overdue or due this week
A2: =COUNTIF(APPLICANTS!N:N,"Overdue")&" overdue, "&COUNTIF(APPLICANTS!N:N,"Due this week")&" due this week" -> 12 overdue, 4 due this week
A3: # | B3: Student ID | C3: Name | D3: Office | E3: Status | F3: Missing Documents | G3: Next Deadline | H3: Days Left | I3: Priority | J3: Owner
A4: 1 | B4: =IFERROR(INDEX(APPLICANTS!A:A,MATCH($A4,APPLICANTS!$P:$P,0))&"","") -> STU-001 | C4: =IFERROR(INDEX(APPLICANTS!B:B,MATCH($A4,APPLICANTS!$P:$P,0))&"","") -> Test Student | D4: =IFERROR(INDEX(APPLICANTS!D:D,MATCH($A4,APPLICANTS!$P:$P,0))&"","") | E4: =IFERROR(INDEX(APPLICANTS!I:I,MATCH($A4,APPLICANTS!$P:$P,0))&"","") -> Applied | F4: =IFERROR(INDEX(APPLICANTS!K:K,MATCH($A4,APPLICANTS!$P:$P,0))&"","") | G4: =IFERROR(INDEX(APPLICANTS!L:L,MATCH($A4,APPLICANTS!$P:$P,0)),"") -> 46285 | H4: =IFERROR(INDEX(APPLICANTS!M:M,MATCH($A4,APPLICANTS!$P:$P,0)),"") -> -6 | I4: =IFERROR(INDEX(APPLICANTS!N:N,MATCH($A4,APPLICANTS!$P:$P,0))&"","") -> Overdue | J4: =IFERROR(INDEX(APPLICANTS!O:O,MATCH($A4,APPLICANTS!$P:$P,0))&"","")
A5: 2 | B5: =IFERROR(INDEX(APPLICANTS!A:A,MATCH($A5,APPLICANTS!$P:$P,0))&"","") -> STU-007 | C5: =IFERROR(INDEX(APPLICANTS!B:B,MATCH($A5,APPLICANTS!$P:$P,0))&"","") -> Blessing Adebayo | D5: =IFERROR(INDEX(APPLICANTS!D:D,MATCH($A5,APPLICANTS!$P:$P,0))&"","") -> Abuja | E5: =IFERROR(INDEX(APPLICANTS!I:I,MATCH($A5,APPLICANTS!$P:$P,0))&"","") -> Applied | F5: =IFERROR(INDEX(APPLICANTS!K:K,MATCH($A5,APPLICANTS!$P:$P,0))&"","") -> Proof of funds | G5: =IFERROR(INDEX(APPLICANTS!L:L,MATCH($A5,APPLICANTS!$P:$P,0)),"") -> 46285 | H5: =IFERROR(INDEX(APPLICANTS!M:M,MATCH($A5,APPLICANTS!$P:$P,0)),"") -> -6 | I5: =IFERROR(INDEX(APPLICANTS!N:N,MATCH($A5,APPLICANTS!$P:$P,0))&"","") -> Overdue | J5: =IFERROR(INDEX(APPLICANTS!O:O,MATCH($A5,APPLICANTS!$P:$P,0))&"","") -> Advisor 1
A6: 3 | B6: =IFERROR(INDEX(APPLICANTS!A:A,MATCH($A6,APPLICANTS!$P:$P,0))&"","") -> STU-009 | C6: =IFERROR(INDEX(APPLICANTS!B:B,MATCH($A6,APPLICANTS!$P:$P,0))&"","") -> Blessing Mensah | D6: =IFERROR(INDEX(APPLICANTS!D:D,MATCH($A6,APPLICANTS!$P:$P,0))&"","") -> Dublin | E6: =IFERROR(INDEX(APPLICANTS!I:I,MATCH($A6,APPLICANTS!$P:$P,0))&"","") -> Documents | F6: =IFERROR(INDEX(APPLICANTS!K:K,MATCH($A6,APPLICANTS!$P:$P,0))&"","") -> Transcript, English test | G6: =IFERROR(INDEX(APPLICANTS!L:L,MATCH($A6,APPLICANTS!$P:$P,0)),"") -> 46287 | H6: =IFERROR(INDEX(APPLICANTS!M:M,MATCH($A6,APPLICANTS!$P:$P,0)),"") -> -4 | I6: =IFERROR(INDEX(APPLICANTS!N:N,MATCH($A6,APPLICANTS!$P:$P,0))&"","") -> Overdue | J6: =IFERROR(INDEX(APPLICANTS!O:O,MATCH($A6,APPLICANTS!$P:$P,0))&"","") -> Advisor 1
A7: 4 | B7: =IFERROR(INDEX(APPLICANTS!A:A,MATCH($A7,APPLICANTS!$P:$P,0))&"","") -> STU-011 | C7: =IFERROR(INDEX(APPLICANTS!B:B,MATCH($A7,APPLICANTS!$P:$P,0))&"","") -> Daniel Nwosu | D7: =IFERROR(INDEX(APPLICANTS!D:D,MATCH($A7,APPLICANTS!$P:$P,0))&"","") -> Dublin | E7: =IFERROR(INDEX(APPLICANTS!I:I,MATCH($A7,APPLICANTS!$P:$P,0))&"","") -> Applied | F7: =IFERROR(INDEX(APPLICANTS!K:K,MATCH($A7,APPLICANTS!$P:$P,0))&"","") -> Reference letter | G7: =IFERROR(INDEX(APPLICANTS!L:L,MATCH($A7,APPLICANTS!$P:$P,0)),"") -> 46279 | H7: =IFERROR(INDEX(APPLICANTS!M:M,MATCH($A7,APPLICANTS!$P:$P,0)),"") -> -12 | I7: =IFERROR(INDEX(APPLICANTS!N:N,MATCH($A7,APPLICANTS!$P:$P,0))&"","") -> Overdue | J7: =IFERROR(INDEX(APPLICANTS!O:O,MATCH($A7,APPLICANTS!$P:$P,0))&"","") -> Advisor 1
A8: 5 | B8: =IFERROR(INDEX(APPLICANTS!A:A,MATCH($A8,APPLICANTS!$P:$P,0))&"","") -> STU-013 | C8: =IFERROR(INDEX(APPLICANTS!B:B,MATCH($A8,APPLICANTS!$P:$P,0))&"","") -> Bola Ogunleye | D8: =IFERROR(INDEX(APPLICANTS!D:D,MATCH($A8,APPLICANTS!$P:$P,0))&"","") -> Dublin | E8: =IFERROR(INDEX(APPLICANTS!I:I,MATCH($A8,APPLICANTS!$P:$P,0))&"","") -> Applied | F8: =IFERROR(INDEX(APPLICANTS!K:K,MATCH($A8,APPLICANTS!$P:$P,0))&"","") -> English test | G8: =IFERROR(INDEX(APPLICANTS!L:L,MATCH($A8,APPLICANTS!$P:$P,0)),"") -> 46294 | H8: =IFERROR(INDEX(APPLICANTS!M:M,MATCH($A8,APPLICANTS!$P:$P,0)),"") -> 3 | I8: =IFERROR(INDEX(APPLICANTS!N:N,MATCH($A8,APPLICANTS!$P:$P,0))&"","") -> Due this week | J8: =IFERROR(INDEX(APPLICANTS!O:O,MATCH($A8,APPLICANTS!$P:$P,0))&"","") -> Advisor 2
A9: 6 | B9: =IFERROR(INDEX(APPLICANTS!A:A,MATCH($A9,APPLICANTS!$P:$P,0))&"","") -> STU-014 | C9: =IFERROR(INDEX(APPLICANTS!B:B,MATCH($A9,APPLICANTS!$P:$P,0))&"","") -> Ama Ibe | D9: =IFERROR(INDEX(APPLICANTS!D:D,MATCH($A9,APPLICANTS!$P:$P,0))&"","") -> Abuja | E9: =IFERROR(INDEX(APPLICANTS!I:I,MATCH($A9,APPLICANTS!$P:$P,0))&"","") -> Enquiry | F9: =IFERROR(INDEX(APPLICANTS!K:K,MATCH($A9,APPLICANTS!$P:$P,0))&"","") -> Degree certificate, English test, Reference letter | G9: =IFERROR(INDEX(APPLICANTS!L:L,MATCH($A9,APPLICANTS!$P:$P,0)),"") -> 46288 | H9: =IFERROR(INDEX(APPLICANTS!M:M,MATCH($A9,APPLICANTS!$P:$P,0)),"") -> -3 | I9: =IFERROR(INDEX(APPLICANTS!N:N,MATCH($A9,APPLICANTS!$P:$P,0))&"","") -> Overdue | J9: =IFERROR(INDEX(APPLICANTS!O:O,MATCH($A9,APPLICANTS!$P:$P,0))&"","") -> Advisor 3
A10: 7 | B10: =IFERROR(INDEX(APPLICANTS!A:A,MATCH($A10,APPLICANTS!$P:$P,0))&"","") -> STU-016 | C10: =IFERROR(INDEX(APPLICANTS!B:B,MATCH($A10,APPLICANTS!$P:$P,0))&"","") -> Ngozi Adeyemi | D10: =IFERROR(INDEX(APPLICANTS!D:D,MATCH($A10,APPLICANTS!$P:$P,0))&"","") -> Dublin | E10: =IFERROR(INDEX(APPLICANTS!I:I,MATCH($A10,APPLICANTS!$P:$P,0))&"","") -> Applied | F10: =IFERROR(INDEX(APPLICANTS!K:K,MATCH($A10,APPLICANTS!$P:$P,0))&"","") -> English test | G10: =IFERROR(INDEX(APPLICANTS!L:L,MATCH($A10,APPLICANTS!$P:$P,0)),"") -> 46295 | H10: =IFERROR(INDEX(APPLICANTS!M:M,MATCH($A10,APPLICANTS!$P:$P,0)),"") -> 4 | I10: =IFERROR(INDEX(APPLICANTS!N:N,MATCH($A10,APPLICANTS!$P:$P,0))&"","") -> Due this week | J10: =IFERROR(INDEX(APPLICANTS!O:O,MATCH($A10,APPLICANTS!$P:$P,0))&"","") -> Advisor 2
A11: 8 | B11: =IFERROR(INDEX(APPLICANTS!A:A,MATCH($A11,APPLICANTS!$P:$P,0))&"","") -> STU-018 | C11: =IFERROR(INDEX(APPLICANTS!B:B,MATCH($A11,APPLICANTS!$P:$P,0))&"","") -> Wanjiru Asante | D11: =IFERROR(INDEX(APPLICANTS!D:D,MATCH($A11,APPLICANTS!$P:$P,0))&"","") -> Abuja | E11: =IFERROR(INDEX(APPLICANTS!I:I,MATCH($A11,APPLICANTS!$P:$P,0))&"","") -> Offer | F11: =IFERROR(INDEX(APPLICANTS!K:K,MATCH($A11,APPLICANTS!$P:$P,0))&"","") -> Proof of funds | G11: =IFERROR(INDEX(APPLICANTS!L:L,MATCH($A11,APPLICANTS!$P:$P,0)),"") -> 46280 | H11: =IFERROR(INDEX(APPLICANTS!M:M,MATCH($A11,APPLICANTS!$P:$P,0)),"") -> -11 | I11: =IFERROR(INDEX(APPLICANTS!N:N,MATCH($A11,APPLICANTS!$P:$P,0))&"","") -> Overdue | J11: =IFERROR(INDEX(APPLICANTS!O:O,MATCH($A11,APPLICANTS!$P:$P,0))&"","") -> Advisor 2
A12: 9 | B12: =IFERROR(INDEX(APPLICANTS!A:A,MATCH($A12,APPLICANTS!$P:$P,0))&"","") -> STU-019 | C12: =IFERROR(INDEX(APPLICANTS!B:B,MATCH($A12,APPLICANTS!$P:$P,0))&"","") -> Zainab Adeyemi | D12: =IFERROR(INDEX(APPLICANTS!D:D,MATCH($A12,APPLICANTS!$P:$P,0))&"","") -> Abuja | E12: =IFERROR(INDEX(APPLICANTS!I:I,MATCH($A12,APPLICANTS!$P:$P,0))&"","") -> Enquiry | F12: =IFERROR(INDEX(APPLICANTS!K:K,MATCH($A12,APPLICANTS!$P:$P,0))&"","") -> Proof of funds, Reference letter | G12: =IFERROR(INDEX(APPLICANTS!L:L,MATCH($A12,APPLICANTS!$P:$P,0)),"") -> 46284 | H12: =IFERROR(INDEX(APPLICANTS!M:M,MATCH($A12,APPLICANTS!$P:$P,0)),"") -> -7 | I12: =IFERROR(INDEX(APPLICANTS!N:N,MATCH($A12,APPLICANTS!$P:$P,0))&"","") -> Overdue | J12: =IFERROR(INDEX(APPLICANTS!O:O,MATCH($A12,APPLICANTS!$P:$P,0))&"","") -> Advisor 2
A13: 10 | B13: =IFERROR(INDEX(APPLICANTS!A:A,MATCH($A13,APPLICANTS!$P:$P,0))&"","") -> STU-021 | C13: =IFERROR(INDEX(APPLICANTS!B:B,MATCH($A13,APPLICANTS!$P:$P,0))&"","") -> Chidi Asante | D13: =IFERROR(INDEX(APPLICANTS!D:D,MATCH($A13,APPLICANTS!$P:$P,0))&"","") -> Abuja | E13: =IFERROR(INDEX(APPLICANTS!I:I,MATCH($A13,APPLICANTS!$P:$P,0))&"","") -> Offer | F13: =IFERROR(INDEX(APPLICANTS!K:K,MATCH($A13,APPLICANTS!$P:$P,0))&"","") -> Reference letter | G13: =IFERROR(INDEX(APPLICANTS!L:L,MATCH($A13,APPLICANTS!$P:$P,0)),"") -> 46287 | H13: =IFERROR(INDEX(APPLICANTS!M:M,MATCH($A13,APPLICANTS!$P:$P,0)),"") -> -4 | I13: =IFERROR(INDEX(APPLICANTS!N:N,MATCH($A13,APPLICANTS!$P:$P,0))&"","") -> Overdue | J13: =IFERROR(INDEX(APPLICANTS!O:O,MATCH($A13,APPLICANTS!$P:$P,0))&"","") -> Advisor 3
A14: 11 | B14: =IFERROR(INDEX(APPLICANTS!A:A,MATCH($A14,APPLICANTS!$P:$P,0))&"","") -> STU-024 | C14: =IFERROR(INDEX(APPLICANTS!B:B,MATCH($A14,APPLICANTS!$P:$P,0))&"","") -> Ama Owusu | D14: =IFERROR(INDEX(APPLICANTS!D:D,MATCH($A14,APPLICANTS!$P:$P,0))&"","") -> Abuja | E14: =IFERROR(INDEX(APPLICANTS!I:I,MATCH($A14,APPLICANTS!$P:$P,0))&"","") -> Applied | F14: =IFERROR(INDEX(APPLICANTS!K:K,MATCH($A14,APPLICANTS!$P:$P,0))&"","") | G14: =IFERROR(INDEX(APPLICANTS!L:L,MATCH($A14,APPLICANTS!$P:$P,0)),"") -> 46284 | H14: =IFERROR(INDEX(APPLICANTS!M:M,MATCH($A14,APPLICANTS!$P:$P,0)),"") -> -7 | I14: =IFERROR(INDEX(APPLICANTS!N:N,MATCH($A14,APPLICANTS!$P:$P,0))&"","") -> Overdue | J14: =IFERROR(INDEX(APPLICANTS!O:O,MATCH($A14,APPLICANTS!$P:$P,0))&"","") -> Advisor 2
A15: 12 | B15: =IFERROR(INDEX(APPLICANTS!A:A,MATCH($A15,APPLICANTS!$P:$P,0))&"","") -> STU-025 | C15: =IFERROR(INDEX(APPLICANTS!B:B,MATCH($A15,APPLICANTS!$P:$P,0))&"","") -> Daniel Abubakar | D15: =IFERROR(INDEX(APPLICANTS!D:D,MATCH($A15,APPLICANTS!$P:$P,0))&"","") -> Abuja | E15: =IFERROR(INDEX(APPLICANTS!I:I,MATCH($A15,APPLICANTS!$P:$P,0))&"","") -> Applied | F15: =IFERROR(INDEX(APPLICANTS!K:K,MATCH($A15,APPLICANTS!$P:$P,0))&"","") | G15: =IFERROR(INDEX(APPLICANTS!L:L,MATCH($A15,APPLICANTS!$P:$P,0)),"") -> 46284 | H15: =IFERROR(INDEX(APPLICANTS!M:M,MATCH($A15,APPLICANTS!$P:$P,0)),"") -> -7 | I15: =IFERROR(INDEX(APPLICANTS!N:N,MATCH($A15,APPLICANTS!$P:$P,0))&"","") -> Overdue | J15: =IFERROR(INDEX(APPLICANTS!O:O,MATCH($A15,APPLICANTS!$P:$P,0))&"","") -> Advisor 1
... A53: 50 | B53: =IFERROR(INDEX(APPLICANTS!A:A,MATCH($A53,APPLICANTS!$P:$P,0))&"","") | C53: =IFERROR(INDEX(APPLICANTS!B:B,MATCH($A53,APPLICANTS!$P:$P,0))&"","") | D53: =IFERROR(INDEX(APPLICANTS!D:D,MATCH($A53,APPLICANTS!$P:$P,0))&"","") | E53: =IFERROR(INDEX(APPLICANTS!I:I,MATCH($A53,APPLICANTS!$P:$P,0))&"","") | F53: =IFERROR(INDEX(APPLICANTS!K:K,MATCH($A53,APPLICANTS!$P:$P,0))&"","") | G53: =IFERROR(INDEX(APPLICANTS!L:L,MATCH($A53,APPLICANTS!$P:$P,0)),"") | H53: =IFERROR(INDEX(APPLICANTS!M:M,MATCH($A53,APPLICANTS!$P:$P,0)),"") | I53: =IFERROR(INDEX(APPLICANTS!N:N,MATCH($A53,APPLICANTS!$P:$P,0))&"","") | J53: =IFERROR(INDEX(APPLICANTS!O:O,MATCH($A53,APPLICANTS!$P:$P,0))&"","")
